Workbook

Sheet Readme
A1: Búsqueda de palabras clave para detectar obligaciones
A2: debe
A3: deberá
A4: prestará
A5: estará
A6: le corresponderá
A7: será obligación
A8: podrá | B8: Se refiere a atribución que puede o no hacer
A10: Referencias consultadas y personas influyentes
A11: José Inostroza | B11: Gobierno Digital
A12: Claudio Reyes | B12: Secretaría de Modernización
A13: Daniel Álvarez | B13: U de Chile
A14: Alejandro Barros | B14: U de Chile
A15: Pilar Díaz Ellis | B15: Archivo Nacional
A16: Gabriela Andaur | B16: Archivo Nacional
A17: Allen Guerra | B17: BCN
A18: Carla Illanes Contreras | B18: DLA Piper Chile
A19: Rosa Gómez | B19: U de Los Andes | C19: https://www.uandes.cl/personas/gomez-gonzalez-rosa-fernanda/
A20: Romina Garrido | B20: GobLab UAI
A21: Sergio Bijman | B21: TakeUp
A22: Renato Jijena | B22: PUCV
A23: Andrés Pumarino | B23: LegalTrust
A25: En el registro los párrafos que contienen más de una obligación se repiten para mantener una obligación por fila.
A26: En las normas técnicas pueden haber imágenes que no son transferidas al registro
A28: Lecciones
A29: Todo debe ir al formato de la BCN, porque cumple estándares. Evitar el uso de pdf o cualquier otro archivo que no se pueda leer como texto directo desde el sitio Web.
A30: Las leyes y reglamentos se actualizan en la BCN, por lo que se debe mirar la fecha de obtención y carga en la base de Normativa.
A32: Ayuda a visibilizar normativa que puede estar omitiéndose del ecosistema de la Ley Nº 21.180
A34: Retroalimentación para la BCN
A35: Mal separados o que pudieran tener una mejor organización
A36: Decreto MINDEF Política de ciberdefensa 2018-3
A38: Grupo A | B38: Ministerios; Servicios Públicos; Contraloría General de la República; Fuerzas Armadas; Fuerzas de Orden y Seguridad; y delegaciones presidenciales regionales provinciales.
A39: Grupo B | B39: Gobiernos Regionales y Municipios de clasificación 1 y 2
A40: Grupo C | B40: Municipios clasificados en los grupos de categoría 3,4 y 5 (Subdere)
A42: 1. Comunicaciones oficiales entre los órganos de la Administración del Estado | B42: 1. Comunicaciones oficiales entre los órganos de la Administración del Estado: Dichas comunicaciones deberán realizarse según lo dispuesto en el inciso sexto del artículo 19 de la ley Nº 19.880 y su respectivo reglamento.
A43: 2. Notificaciones | B43: 2. Notificaciones: La copia de todas las notificaciones que se realicen dentro de un procedimiento administrativo se incluirán en el Domicilio Digital Único de los interesados, que regulan los artículos 30 y 46 de la ley Nº 19.880 y su respectivo reglamento. Lo señalado en el párrafo anterior en ningún caso reemplazará a la notificación realizada por el medio establecido por la ley especial.
A44: 3. Registro de actuaciones en expedientes electrónicos | B44: 3. Registro de actuaciones en expedientes electrónicos: las actuaciones realizadas por medios distintos al electrónico se deberán registrar, debiendo para ello digitalizarlas e incluirlas en el expediente electrónico respectivo, según lo dispuesto en el inciso segundo del artículo 1º, los incisos tercero y sexto del artículo 18 y en el artículo 19 de la ley Nº 19.880 y su respectivo reglamento.
A45: 4. Principio de interoperabilidad | B45: 4. Principio de interoperabilidad: este principio se ajustará a lo dispuesto en los incisos segundo y quinto del artículo 16 bis de la ley Nº 19.880 y su respectivo reglamento.
A47: Fase de Preparación | B47: Cada órgano de la Administración deberá identificar y describir las etapas de los procedimientos administrativos que desarrolla, y en particular la necesidad de notificación en cada uno de ellos. La División de Gobierno Digital del Ministerio Secretaría General de la Presidencia entregará las orientaciones técnicas respecto de esta fase. | C47: =A47&": "&B47 -> Fase de Preparación: Cada órgano de la Administración deberá identificar y describir las etapas de los procedimientos administrativos que desarrolla, y en particular la necesidad de notificación en cada uno de ellos. La División de Gobierno Digital del Ministerio Secretaría General de la Presidencia entregará las orientaciones técnicas respecto de esta fase.
A48: Fase 1 Comunicaciones oficiales | B48: Las comunicaciones oficiales entre los órganos de la Administración serán registradas en una plataforma electrónica destinada al efecto, en virtud de lo dispuesto en el inciso sexto del artículo 19 de la ley Nº 19.880. | C48: =A48&": "&B48 -> Fase 1 Comunicaciones oficiales: Las comunicaciones oficiales entre los órganos de la Administración serán registradas en una plataforma electrónica destinada al efecto, en virtud de lo dispuesto en el inciso sexto del artículo 19 de la ley Nº 19.880.
...

Sheet Normativa
B2: =SUM(B5:B102) -> 12769
A3: ID_normativa | B3: Carga | C3: Tipo de normativa | D3: Acción | E3: Acción_que_realiza_a | F3: Link | G3: Responsable | H3: Materia | I3: Fecha_de_Publicación | J3: Fecha de obtención | K3: Texto | L3: Complemento_texto_1 | M3: Complemento_texto_2 | N3: Origen de la norma | O3: Complemento_origen
B4: =if(A4="","", countif(Obligaciones!$D$3:$D$20388,A4))
A5: Ley 19799 | B5: =if(A5="","", countif(Obligaciones!$D$3:$D$20388,A5)) -> 184 | C5: Ley | D5: Original | F5: https://bcn.cl/2f6mw | G5: Ministerio de Economía, Fomento y Reconstrucción | H5: Sobre documentos electrónicos, firma electrónica y servicios de certificación de dicha firma | I5: 37358 | J5: 45064 | K5: Ley 19.799: Sobre Documentos Electrónicos, Firma Electrónica y Servicios de Certificación de Dicha Firma. | L5: Fecha de publicación: v.Año: 2002 | M5: Establece la forma en que las instituciones del Estado deben llevar a... | N5: https://digital.gob.cl/biblioteca/regulacion/
A6: Decreto MINECON 2002-181 | B6: =if(A6="","", countif(Obligaciones!$D$3:$D$20388,A6)) -> 369 | C6: Reglamento | D6: Original | F6: https://bcn.cl/3cxw0 | G6: Ministerio de Economía, Fomento y Reconstrucción | H6: Sobre documentos electrónicos, firma electrónica y servicios de certificación de dicha firma | I6: 37485 | J6: 45064 | K6: Decreto Nº181 DECRETO 181 APRUEBA REGLAMENTO DE LA LEY 19.799 SOBRE DOCUMENTOS ELECTRONICOS, FIRMA ELECTRONICA Y LA CERTIFICACION DE DICHA FIRMA. MINISTERIO DE ECONOMÍA; FOMENTO Y RECONSTRUCCION; SUBSECRETARIA DE ECONOMIA; FOMENTO Y RECONSTRUCCION | L6: Fecha de publicación: v.Año: 2002 | M6: Reglamento de la Ley Nº 19.799 sobre documentos electrónicos, firma... | N6: https://digital.gob.cl/biblioteca/regulacion/
A7: Decreto MINECON 2006-348 | B7: =if(A7="","", countif(Obligaciones!$D$3:$D$20388,A7)) -> 0 | C7: Reglamento | D7: Modifica a | E7: Decreto MINECON 2002-181 | F7: https://bcn.cl/3cxvy | G7: Ministerio de Economía, Fomento y Reconstrucción | H7: Sobre documentos electrónicos, firma electrónica y servicios de certificación de dicha firma | I7: 38749 | J7: 45064 | K7: DECRETO 348 MODIFICA DECRETO Nº 181, DE 2002 MINISTERIO DE ECONOMÍA; FOMENTO Y RECONSTRUCCION; SUBSECRETARIA DE ECONOMIA; FOMENTO Y RECONSTRUCCION | N7: BCN
A8: Decreto MINECON 2012-154 | B8: =if(A8="","", countif(Obligaciones!$D$3:$D$20388,A8)) -> 0 | C8: Reglamento | D8: Modifica a | E8: Decreto MINECON 2002-181 | F8: https://bcn.cl/3cxw1 | G8: Ministerio de Economía, Fomento y Reconstrucción | H8: Sobre documentos electrónicos, firma electrónica y servicios de certificación de dicha firma | I8: 41132 | J8: 45064 | K8: 11-AGO-2012 DECRETO 154 - ARTÍCULO PRIMERO. MODIFICA DECRETO N° 181, DE 2002, QUE APRUEBA REGLAMENTO DE LA LEY Nº 19.799 SOBRE DOCUMENTOS ELECTRÓNICOS, FIRMA ELECTRÓNICA Y LA CERTIFICACIÓN DE DICHA FIRMA. MINISTERIO DE ECONOMÍA, FOMENTO Y TURISMO;SUBSECRETARÍA DE ECONOMÍA Y EMPRESAS DE MENOR TAMAÑO | N8: BCN
A9: Decreto MINECON 2014-14 | B9: =if(A9="","", countif(Obligaciones!$D$3:$D$20388,A9)) -> 0 | C9: Reglamento | D9: Modifica a | E9: Decreto MINECON 2002-181 | F9: https://bcn.cl/2r3hy | G9: Ministerio de Economía, Fomento y Reconstrucción | H9: Sobre documentos electrónicos, firma electrónica y servicios de certificación de dicha firma | I9: 41697 | J9: 45064 | K9: DECRETO 14 MODIFICA DECRETO Nº 181, DE 2002, QUE APRUEBA REGLAMENTO DE LA LEY 19.799 SOBRE DOCUMENTOS ELECTRÓNICOS, FIRMA ELECTRÓNICA Y LA CERTIFICACIÓN DE DICHA FIRMA, Y DEROGA LOS DECRETOS QUE INDICA. MINISTERIO DE ECONOMÍA, FOMENTO Y TURISMO; SUBSECRETARÍA DE ECONOMÍA Y EMPRESAS DE MENOR TAMAÑO | N9: https://digital.gob.cl/biblioteca/regulacion/
A10: Decreto MINECON 2019-24 | B10: =if(A10="","", countif(Obligaciones!$D$3:$D$20388,A10)) -> 35 | C10: Norma técnica | D10: Complementa a | E10: Ley 19799 | F10: https://bcn.cl/2gwjg | G10: Ministerio de Economía, Fomento y Reconstrucción | H10: Sobre documentos electrónicos, firma electrónica y servicios de certificación de dicha firma | I10: 43564 | J10: 45064 | K10: DECRETO 24 APRUEBA NORMA TÉCNICA PARA LA PRESTACIÓN DEL SERVICIO DE CERTIFICACIÓN DE FIRMA ELECTRÓNICA AVANZADA. MINISTERIO DE ECONOMÍA, FOMENTO Y TURISMO; SUBSECRETARÍA DE ECONOMÍA Y EMPRESAS DE MENOR TAMAÑO | L10: Fecha de publicación: v.Año: 2019 | M10: Aprueba norma técnica para la prestación de servicios de... | N10: https://digital.gob.cl/biblioteca/regulacion/
A11: Decreto MINSEGPRES 2015-1 | B11: =if(A11="","", countif(Obligaciones!$D$3:$D$20388,A11)) -> 92 | C11: Norma técnica | D11: Complementa a | E11: Ley 19799 | F11: https://bcn.cl/2m5gb | G11: Ministerio Secretaría General de la Presidencia | H11: Sobre sistemas y sitios web de los órganos de la administración del Estado | I11: 42166 | J11: 45064 | K11: DECRETO 1 APRUEBA NORMA TÉCNICA SOBRE SISTEMAS Y SITIOS WEB DE LOS ÓRGANOS DE LA ADMINISTRACIÓN DEL ESTADO. MINISTERIO SECRETARÍA GENERAL DE LA PRESIDENCIA | L11: Fecha de publicación: v.Año: 2015 | M11: Aprueba norma técnica sobre sistemas y sitios web de los órganos de la... | N11: https://digital.gob.cl/biblioteca/regulacion/
A12: Decreto MINSEGPRES 2006-93 | B12: =if(A12="","", countif(Obligaciones!$D$3:$D$20388,A12)) -> 0 | C12: Norma técnica | D12: Complementa a | E12: Ley 19799 | F12: https://bcn.cl/2o11a | G12: Ministerio Secretaría General de la Presidencia | H12: Sobre mensajes no deseados recibidos por el Estado y sus funcionarios/as | I12: 38926 | J12: 45064 | K12: DECRETO 93 APRUEBA NORMA TECNICA PARA LA ADOPCION DE MEDIDAS DESTINADAS A MINIMIZAR LOS EFECTOS PERJUDICIALES DE LOS MENSAJES ELECTRONICOS MASIVOS NO SOLICITADOS RECIBIDOS EN LAS CASILLAS ELECTRONICAS DE LOS ORGANOS DE LA ADMINISTRACION DEL ESTADO Y DE SUS FUNCIONARIOS. MINISTERIO SECRETARÍA GENERAL DE LA PRESIDENCIA | L12: Fecha de publicación: v.Año: 2006 | M12: Aprueba norma técnica para la adopción de medidas destinadas a minimizar... | N12: https://digital.gob.cl/biblioteca/regulacion/
A13: Decreto MINSEGPRES 2005-83 | B13: =if(A13="","", countif(Obligaciones!$D$3:$D$20388,A13)) -> 0 | C13: Norma técnica | D13: Complementa a | E13: Ley 19799 | F13: https://bcn.cl/2kdhg | G13: Ministerio Secretaría General de la Presidencia | H13: Sobre seguridad y confidencialidad de los documentos electrónicos | I13: 38364 | J13: 45064 | K13: DECRETO 83 APRUEBA NORMA TECNICA PARA LOS ORGANOS DE LA ADMINISTRACION DEL ESTADO SOBRE SEGURIDAD Y CONFIDENCIALIDAD DE LOS DOCUMENTOS ELECTRONICOS. MINISTERIO SECRETARÍA GENERAL DE LA PRESIDENCIA | L13: Fecha de publicación: v.Año: 2005 | M13: Aprueba norma técnica para los órganos de la administración del Estado sobre... | N13: https://digital.gob.cl/biblioteca/regulacion/
B14: =if(A14="","", countif(Obligaciones!$D$3:$D$20388,A14))
A15: Ley 18993 | B15: =if(A15="","", countif(Obligaciones!$D$3:$D$20388,A15)) -> 0 | C15: Ley | D15: Original | F15: https://bcn.cl/3cxwf | G15: Ministerio del Interior | H15: Sobre la institucionalidad de la División de Gobierno Digital | I15: 33106 | J15: 45064 | K15: LEY 18993 CREA MINISTERIO SECRETARIA GENERAL DE LA PRESIDENCIA DE LA REPUBLICA. MINISTERIO DEL INTERIOR
A16: Ley 21050 | B16: =if(A16="","", countif(Obligaciones!$D$3:$D$20388,A16)) -> 0 | C16: Ley | D16: Original | F16: https://bcn.cl/2kam1 | G16: Ministerio de Hacienda | H16: Sobre la institucionalidad de la División de Gobierno Digital | I16: 43076 | J16: 45064 | K16: Ley Nº 21.050: Otorga reajuste de remuneraciones a los trabajadores del sector público, concede aguinaldos que señala, concede otros beneficios que indica y modifica diversos cuerpos legales. | L16: Fecha de publicación: v.Año: 2017 | M16: Ley que modifica la ley N° 18.993 que crea Ministerio Secretaría General de... | N16: https://digital.gob.cl/biblioteca/regulacion/
A17: Ley 21045 | B17: =if(A17="","", countif(Obligaciones!$D$3:$D$20388,A17)) -> 507 | C17: Ley | D17: Original | F17: https://bcn.cl/2f7iu | G17: Ministerio de Educación | H17: Sobre la institucionalidad del Archivo Nacional | I17: 43042 | J17: 45064 | K17: LEY 21045 Firma electrónica CREA EL MINISTERIO DE LAS CULTURAS, LAS ARTES Y EL PATRIMONIO. MINISTERIO DE EDUCACIÓN
A18: DFL MINEDUC 1929-5200 | B18: =if(A18="","", countif(Obligaciones!$D$3:$D$20388,A18)) -> 130 | C18: Decreto con Fuerza de Ley | D18: Original | F18: https://bcn.cl/2fa2y | G18: Ministerio de Educación | H18: Sobre la institucionalidad del Archivo Nacional | I18: 10937 | J18: 45064 | K18: DFL 5200 SOBRE INSTITUCIONES NACIONALES PATRIMONIALES DEPENDIENTES DEL SERVICIO NACIONAL DEL PATRIMONIO CULTURAL. MINISTERIO DE EDUCACIÓN PÚBLICA
A19: Decreto MINSEGPRES 2018-12 | B19: =if(A19="","", countif(Obligaciones!$D$3:$D$20388,A19)) -> 0 | C19: Decreto | D19: Original | F19: https://bcn.cl/2rlya | G19: Ministerio Secretaría General de la Presidencia | H19: Sobre la institucionalidad del Consejo Asesor Permanente para la Modernización del Estado y la Secretaría de Modernización del Estado | I19: 43461 | J19: 45064 | K19: DECRETO 12 CREA "CONSEJO ASESOR PERMANENTE PARA LA MODERNIZACIÓN DEL ESTADO" Y ORGANIZA LA "SECRETARÍA DE MODERNIZACIÓN DEL ESTADO". MINISTERIO SECRETARÍA GENERAL DE LA PRESIDENCIA
A20: Decreto MINSEGPRES 2021-5 | B20: =if(A20="","", countif(Obligaciones!$D$3:$D$20388,A20)) -> 0 | C20: Decreto | D20: Modifica a | E20: Decreto MINSEGPRES 2018-12 | F20: https://bcn.cl/3cxwo | G20: Ministerio Secretaría General de la Presidencia | H20: Sobre la institucionalidad del Consejo Asesor Permanente para la Modernización del Estado y la Secretaría de Modernización del Estado | I20: 44411 | J20: 45064 | K20: DECRETO 5 MODIFICA DECRETO SUPREMO N° 12, DE 25 DE JUNIO DE 2018, DEL MINISTERIO SECRETARÍA GENERAL DE LA PRESIDENCIA, EN EL SENTIDO QUE SE SEÑALA, Y RENUEVA Y DESIGNA MIEMBROS QUE INDICA DEL CONSEJO ASESOR PERMANENTE PARA LA MODERNIZACIÓN DEL ESTADO. MINISTERIO SECRETARÍA GENERAL DE LA PRESIDENCIA
A21: Decreto MINSEGPRES 2022-19 | B21: =if(A21="","", countif(Obligaciones!$D$3:$D$20388,A21)) -> 0 | C21: Decreto | D21: Modifica a | E21: Decreto MINSEGPRES 2018-12 | F21: https://bcn.cl/3cxwp | G21: Ministerio Secretaría General de la Presidencia | H21: Sobre la institucionalidad del Consejo Asesor Permanente para la Modernización del Estado y la Secretaría de Modernización del Estado | I21: 44901 | J21: 45064 | K21: DECRETO 19 MODIFICA DECRETO SUPREMO Nº 12, DE 25 DE JUNIO DE 2018, DEL MINISTERIO SECRETARÍA GENERAL DE LA PRESIDENCIA, EN EL SENTIDO QUE SE SEÑALA, Y RENUEVA Y DESIGNA MIEMBROS QUE INDICA DEL CONSEJO ASESOR PERMANENTE PARA LA MODERNIZACIÓN DEL ESTADO. MINISTERIO SECRETARÍA GENERAL DE LA PRESIDENCIA
A22: Decreto MINECON 2015-44 | B22: =if(A22="","", countif(Obligaciones!$D$3:$D$20388,A22)) -> 0 | C22: Decreto | D22: Original | F22: https://bcn.cl/3cxwq | G22: Ministerio de Economía, Fomento y Reconstrucción | H22: Sobre la institucionalidad del laboratorio de gobierno | I22: 42132 | J22: 45064 | K22: RESOLUCIÓN 44 AFECTA EJECUTA ACUERDO DE CONSEJO Nº 2.867, DE 2015, Y MODIFICA RESOLUCIÓN (A) Nº 50, DE 2014, MODIFICADA POR RESOLUCIONES (A) Nº 7 Y Nº 20, AMBAS DE 2015 Y DE CORFO, QUE APROBÓ EL REGLAMENTO POR EL QUE SE RIGE EL "COMITÉ DE INNOVACIÓN EN EL SECTOR PÚBLICO". MINISTERIO DE ECONOMÍA, FOMENTO Y TURISMO; CORPORACIÓN DE FOMENTO DE LA PRODUCCIÓN
A23: Decreto MINECON 2018-100 | B23: =if(A23="","", countif(Obligaciones!$D$3:$D$20388,A23)) -> 0 | C23: Decreto | D23: Deroga a | F23: https://bcn.cl/3cxwr | G23: Ministerio de Economía, Fomento y Reconstrucción | H23: Sobre la institucionalidad del laboratorio de gobierno | I23: 43404 | J23: 45064 | K23: RESOLUCIÓN 100 EJECUTA ACUERDO DE CONSEJO Nº 2.997, DE 2018, QUE DEJA SIN EFECTO ACUERDOS DE CONSEJO Nº 2.826, DE 2014; Nº 2.859, Nº 2.867 Y Nº 2.895, TODOS DE 2015; Nº 2.924 Y Nº 2.940, AMBOS DE 2016; Y Nº 2.956, DE 2017; CREA EL "COMITÉ DE INNOVACIÓN EN EL SECTOR PÚBLICO"; Y APRUEBA REGLAMENTO DEL COMITÉ. MINISTERIO DE ECONOMÍA, FOMENTO Y TURISMO; CORPORACIÓN DE FOMENTO DE LA PRODUCCIÓN
A24: Decreto MINECON 2020-1314 | B24: =if(A24="","", countif(Obligaciones!$D$3:$D$20388,A24)) -> 0 | C24: Decreto | D24: Pone término | F24: https://bcn.cl/3cxws | G24: Ministerio de Economía, Fomento y Reconstrucción | H24: Sobre la institucionalidad del laboratorio de gobierno | I24: 44187 | J24: 45064 | K24: RESOLUCIÓN 1314 EXENTA EJECUTA ACUERDO DE CONSEJO Nº 3.092, DE 2020, QUE "DEJA SIN EFECTO ACUERDOS DE CONSEJO Nº 2.997, DE 2018 Y Nº 3.031, DE 2019; Y PONE TÉRMINO AL "COMITÉ DE INNOVACIÓN EN EL SECTOR PÚBLICO" MINISTERIO DE ECONOMÍA, FOMENTO Y TURISMO; CORPORACIÓN DE FOMENTO DE LA PRODUCCIÓN
B25: =if(A25="","", countif(Obligaciones!$D$3:$D$20388,A25))
A26: DS MININTERIOR 1999-5996 | B26: =if(A26="","", countif(Obligaciones!$D$3:$D$20388,A26)) -> 0 | C26: Decreto Supremo | D26: Original | F26: https://bcn.cl/2xo8i | G26: Ministerio del Interior | H26: Sobre la red interna (Intranet) del Estado | I26: 36476 | J26: 45064 | K26: Decreto Supremo N°5996, de 1999: Crea Red Interna (INTRANET) del Estado y entrega su implementación, puesta en marcha, administración, coordinación y supervisión al Ministerio del Interior y Seguridad Pública. | N26: CSIRT
A27: DS MININTERIOR 2005-1299 | B27: =if(A27="","", countif(Obligaciones!$D$3:$D$20388,A27)) -> 0 | C27: Decreto Supremo | D27: Complementa a | E27: DS MININTERIOR 1999-5996 | F27: https://bcn.cl/3cy8w | G27: Ministerio del Interior | H27: Sobre la red interna (Intranet) del Estado | I27: 38471 | J27: 45064 | K27: DECRETO 1299 ESTABLECE NUEVAS NORMAS QUE REGULAN LA RED DE CONECTIVIDAD DEL ESTADO QUE ADMINISTRA EL MINISTERIO DEL INTERIOR Y FIJA LOS PROCEDIMIENTOS, REQUISITOS Y ESTANDARES TECNOLOGICOS PARA LA INCORPORACION A DICHA RED DE INSTITUCIONES PUBLICAS. MINISTERIO DEL INTERIOR; SUBSECRETARIA DEL INTERIOR | N27: CSIRT
A28: Decreto MTT 2003-5 | B28: =if(A28="","", countif(Obligaciones!$D$3:$D$20388,A28)) -> 0 | C28: Decreto Supremo | D28: Original | F28: https://bcn.cl/2kfik | G28: Ministerio de Transportes y Telecomunicaciones | H28: Sobre la institucionalidad del Consejo nacional de nombres de dominio y números IP | I28: 37796 | J28: 45064 | K28: DECRETO 5 CREA CONSEJO NACIONAL DE NOMBRES DE DOMINIO Y NUMEROS IP. MINISTERIO DE TRANSPORTES Y TELECOMUNICACIONES; SUBSECRETARIA DE TELECOMUNICACIONES
B29: =if(A29="","", countif(Obligaciones!$D$3:$D$20388,A29))
A30: Ley 18845 | B30: =if(A30="","", countif(Obligaciones!$D$3:$D$20388,A30)) -> 64 | C30: Ley | D30: Modificada por | E30: Ley 21180 | F30: https://bcn.cl/2li93 | G30: Ministerio de Justicia | H30: Sobre sistemas de microcopia o micrograbación de documentos | I30: 32815 | J30: 45064 | K30: LEY 18845 ESTABLECE SISTEMAS DE MICROCOPIA O MICROGRABACION DE DOCUMENTOS. MINISTERIO DE JUSTICIA
A31: Ley 19880 | B31: =if(A31="","", countif(Obligaciones!$D$3:$D$20388,A31)) -> 350 | C31: Ley | D31: Modificada por | E31: Ley 21180 | F31: https://bcn.cl/2f82ee | G31: Ministerio Secretaría General de la Presidencia | H31: Sobre los procedimientos administrativos | I31: 37770 | J31: 45064 | K31: LEY Nº 19880 ESTABLECE BASES DE LOS PROCEDIMIENTOS ADMINISTRATIVOS QUE RIGEN LOS ACTOS DE LOS ORGANOS DE LA ADMINISTRACION DEL ESTADO.. MINISTERIO SECRETARÍA GENERAL DE LA PRESIDENCIA | L31: Fecha de publicación: v.Año: 2003 | M31: Establece la forma en que las instituciones del Estado deben llevar a... | N31: https://digital.gob.cl/biblioteca/regulacion/
A32: Ley 20766 | B32: =if(A32="","", countif(Obligaciones!$D$3:$D$20388,A32)) -> 53 | C32: Ley | D32: Modificada por | E32: Ley 21180 | F32: https://bcn.cl/2pk6k | G32: Ministerio Secretaría General de la Presidencia | H32: Sobre el procedimiento de toma de razón y registros electrónicos | I32: 41843 | J32: 45064 | K32: LEY 20766 Firma electrónica PROCEDIMIENTO DE TOMA DE RAZÓN Y REGISTRO ELECTRÓNICOS. MINISTERIO SECRETARÍA GENERAL DE LA PRESIDENCIA
A34: Ley 21180 | B34: =if(A34="","", countif(Obligaciones!$D$3:$D$20388,A34)) -> 192 | C34: Ley | D34: Original | F34: https://bcn.cl/3cxwe | G34: Ministerio Secretaría General de la Presidencia | H34: Sobre la transformación digital del Estado | I34: 43780 | J34: 45064 | K34: Ley Nº21.180 sobre Transformación Digital del Estado | L34: Fecha de publicación: v.Año: 2019 | M34: Ley que modifica la ley Nº19.880 que establece las bases para los... | N34: https://digital.gob.cl/biblioteca/regulacion/
A35: Ley 21464 | B35: =if(A35="","", countif(Obligaciones!$D$3:$D$20388,A35)) -> 68 | C35: Ley | D35: Modifica a | E35: Ley 21180 | F35: https://bcn.cl/32hvm | G35: Ministerio Secretaría General de la Presidencia | H35: Sobre la transformación digital del Estado | I35: 44721 | J35: 45064 | K35: Ley Nº 21.464 MODIFICA DIVERSOS CUERPOS LEGALES, EN MATERIA DE TRANSFORMACIÓN DIGITAL DEL ESTADO MINISTERIO SECRETARÍA GENERAL DE LA PRESIDENCIA | L35: Fecha de publicación: v.1 | M35: Modifica diversos cuerpos legales en materia de Transformación Digital del... | N35: https://digital.gob.cl/biblioteca/regulacion/
A36: DFL MINSEGPRES 2021-1 | B36: =if(A36="","", countif(Obligaciones!$D$3:$D$20388,A36)) -> 0 | C36: Decreto con Fuerza de Ley | D36: Complementa a | E36: Ley 21180 | F36: https://bcn.cl/2obw9 | G36: Ministerio Secretaría General de la Presidencia | H36: Sobre la gradualidad | I36: 44292 | J36: 45064 | K36: Decreto de gradualidad de la Ley de Transformación Digital 21.180 | L36: Fecha de publicación: v.1, Abril 2021 | M36: Decreto sobre gradualidad de implementación de la Ley de... | N36: https://digital.gob.cl/biblioteca/regulacion/
A37: Decreto MINSEGPRES 2021-4 | B37: =if(A37="","", countif(Obligaciones!$D$3:$D$20388,A37)) -> 0 | C37: Reglamento | D37: Complementa a | E37: Ley 21180 | F37: https://bcn.cl/2uejl | G37: Ministerio Secretaría General de la Presidencia | H37: Sobre los procedimientos administrativos | I37: 44541 | J37: 45064 | K37: Ley de Transformación Digital. Decreto N° 4 | Reglamento. // DECRETO 4 REGLAMENTO QUE REGULA LA FORMA EN QUE LOS PROCEDIMIENTOS ADMINISTRATIVOS DEBERÁN EXPRESARSE A TRAVÉS DE MEDIOS ELECTRÓNICOS, EN LAS MATERIAS QUE INDICA, SEGÚN LO DISPUESTO EN LA LEY Nº 21.180 SOBRE TRANSFORMACIÓN DIGITAL DEL ESTADO. MINISTERIO SECRETARÍA GENERAL DE LA PRESIDENCIA | L37: Fecha de publicación: v.1 | M37: Decreto que regula la forma en que los procedimientos administrativos... | N37: https://digital.gob.cl/biblioteca/regulacion/
A38: DFL MINCULTURAS 2021-1 | B38: =if(A38="","", countif(Obligaciones!$D$3:$D$20388,A38)) -> 0 | C38: Decreto con Fuerza de Ley | D38: Complementa a | E38: Ley 21180 | F38: https://bcn.cl/2o2as | G38: Ministerio de las Culturas, las Artes y el Patrimonio | H38: Sobre las microformas | I38: 44270 | J38: 45064 | K38: DFL 1 DETERMINA LOS REQUISITOS DEL MÉTODO DE ELABORACIÓN, CONSERVACIÓN Y USO DE LAS MICROFORMAS Y DE AQUELLOS A EMPLEAR EN LA DESTRUCCIÓN DE DOCUMENTOS ORIGINALES EN VIRTUD DE LA LEY N° 18.845. MINISTERIO DE LAS CULTURAS, LAS ARTES Y EL PATRIMONIO
A39: Decreto MINCULTURAS 2021-23 | B39: =if(A39="","", countif(Obligaciones!$D$3:$D$20388,A39)) -> 74 | C39: Reglamento | D39: Complementa a | E39: Ley 21180 | F39: https://bcn.cl/2t7yl | G39: Ministerio de las Culturas, las Artes y el Patrimonio | H39: Sobre las microformas | I39: 44490 | J39: 45064 | K39: Ley de Transformación Digital. Decreto N° 23 | Reglamento. // DECRETO 23 APRUEBA EL REGLAMENTO QUE ESTABLECE LOS MEDIOS Y PROCEDIMIENTOS TÉCNICOS Y ADMINISTRATIVOS QUE SE UTILIZARÁN EN LA GENERACIÓN DE MICROFORMAS. MINISTERIO DE LAS CULTURAS, LAS ARTES Y EL PATRIMONIO; SUBSECRETARÍA DEL PATRIMONIO CULTURAL | L39: Fecha de publicación: v.1 | M39: Decreto que establece los medios y procedimientos técnicos y... | N39: https://digital.gob.cl/biblioteca/regulacion/
A40: Decreto MINCULTURAS 2021-24 | B40: =if(A40="","", countif(Obligaciones!$D$3:$D$20388,A40)) -> 0 | C40: Reglamento | D40: Complementa a | E40: Ley 21180 | F40: https://bcn.cl/2vn1a | G40: Ministerio de las Culturas, las Artes y el Patrimonio | H40: Sobre el archivo electrónico del Archivo Nacional | I40: 44490 | J40: 45064 | K40: Ley de Transformación Digital.. Decreto N° 24 | Reglamento. //DECRETO 24 REGLAMENTO QUE ESTABLECE LOS ESTÁNDARES TÉCNICOS Y ADMINISTRATIVOS DEL ARCHIVO ELECTRÓNICO DESARROLLADO POR EL ARCHIVO NACIONAL. MINISTERIO DE LAS CULTURAS, LAS ARTES Y EL PATRIMONIO; SUBSECRETARÍA DEL PATRIMONIO CULTURAL | L40: Fecha de publicación: v.1 | M40: Decreto sobre los estándares técnicos y administrativos del archivo electrónico... | N40: https://digital.gob.cl/biblioteca/regulacion/
A42: Ley 18290 | F42: https://bcn.cl/2lcu2
A43: DFL MTT 2009-1 | B43: =if(A43="","", countif(Obligaciones!$D$3:$D$20388,A43)) -> 2488 | C43: Decreto con Fuerza de Ley | D43: Original | F43: https://bcn.cl/32g67 | G43: Ministerio de Transportes y Telecomunicaciones | H43: Sobre la ley de tránsito | I43: 40115 | J43: 45064 | K43: DFL 1 FIJA TEXTO REFUNDIDO, COORDINADO Y SISTEMATIZADO DE LA LEY DE TRÁNSITO. MINISTERIO DE TRANSPORTES Y TELECOMUNICACIONES; SUBSECRETARÍA DE TRANSPORTES; MINISTERIO DE JUSTICIA; SUBSECRETARÍA DE JUSTICIA
...

Sheet Obligaciones
A1: Obligaciones normativas en materia de Transformación Digital del Estado de Chile
C2: =CONCATENATE(COUNTIF($A$601:$A$648,TRUE), "/", COUNTA($C$601:$C$648), " completed ") -> 0/1 completed
A3: ✓ | B3: Evento/Periodicidad | C3: Obligación | D3: Referencia normativa | E3: Tipo_de_norma | F3: Obligación, definición | G3: Alcance | H3: Texto | I3: n_text | J3: Plan de acción que debe tener cada Órgano de la Administración del Estado (OAE) | K3: Obligación del Estado
A4: FALSE | D4: Ley 19880 | E4: =VLOOKUP(D4,Normativa!$A$3:$C$100,3,0) -> Ley | H4: ESTABLECE BASES DE LOS PROCEDIMIENTOS ADMINISTRATIVOS QUE RIGEN LOS ACTOS DE LOS ORGANOS DE LA ADMINISTRACION DEL ESTADO | I4: =IF(H4=H3,I3+1,1) -> 1
A5: FALSE | D5: Ley 19880 | E5: =VLOOKUP(D5,Normativa!$A$3:$C$100,3,0) -> Ley | I5: =IF(H5=H4,I4+1,1) -> 1
A6: FALSE | D6: Ley 19880 | E6: =VLOOKUP(D6,Normativa!$A$3:$C$100,3,0) -> Ley | H6: Teniendo presente que el H. Congreso Nacional ha dado su aprobación al siguiente | I6: =IF(H6=H5,I5+1,1) -> 1
A7: FALSE | D7: Ley 19880 | E7: =VLOOKUP(D7,Normativa!$A$3:$C$100,3,0) -> Ley | I7: =IF(H7=H6,I6+1,1) -> 1
A8: FALSE | D8: Ley 19880 | E8: =VLOOKUP(D8,Normativa!$A$3:$C$100,3,0) -> Ley | H8: Proyecto de ley: | I8: =IF(H8=H7,I7+1,1) -> 1
A9: FALSE | D9: Ley 19880 | E9: =VLOOKUP(D9,Normativa!$A$3:$C$100,3,0) -> Ley | I9: =IF(H9=H8,I8+1,1) -> 1
A10: FALSE | D10: Ley 19880 | E10: =VLOOKUP(D10,Normativa!$A$3:$C$100,3,0) -> Ley | I10: =IF(H10=H9,I9+1,1) -> 2
A11: FALSE | D11: Ley 19880 | E11: =VLOOKUP(D11,Normativa!$A$3:$C$100,3,0) -> Ley | I11: =IF(H11=H10,I10+1,1) -> 3
A12: FALSE | D12: Ley 19880 | E12: =VLOOKUP(D12,Normativa!$A$3:$C$100,3,0) -> Ley | I12: =IF(H12=H11,I11+1,1) -> 4
A13: FALSE | D13: Ley 19880 | E13: =VLOOKUP(D13,Normativa!$A$3:$C$100,3,0) -> Ley | I13: =IF(H13=H12,I12+1,1) -> 5
A14: FALSE | B14: En la tramitación de un procedimiento administrativo | C14: Todo procedimiento administrativo deberá expresarse a través de los medios electrónicos establecidos por ley, salvo las excepciones legales. En caso de que la ley establezca procedimientos administrativos especiales, la presente ley se aplicará con carácter supletorio. | D14: Ley 19880 | E14: =VLOOKUP(D14,Normativa!$A$3:$C$100,3,0) -> Ley | F14: Obligación | G14: Órganos de la Administración del Estado | H14: CAPITULO I Disposiciones Generales Artículo 1º. Procedimiento Administrativo. La presente ley establece y regula las bases del procedimiento administrativo de los actos de la Administración del Estado. Todo procedimiento administrativo deberá expresarse a través de los medios electrónicos establecidos por ley, salvo las excepciones legales. En caso de que la ley establezca procedimientos administrativos especiales, la presente ley se aplicará con carácter supletorio. La toma de razón de los actos de la Administración del Estado se regirán por lo dispuesto en la Constitución y en la Ley Orgánica Constitucional de la Contraloría General de la República. | I14: =IF(H14=H13,I13+1,1) -> 1
A15: FALSE | D15: Ley 19880 | E15: =VLOOKUP(D15,Normativa!$A$3:$C$100,3,0) -> Ley | H15: Artículo 2º. Ambito de aplicación. Las disposiciones de la presente ley serán aplicables a los ministerios, las intendencias, las gobernaciones y los servicios públicos creados para el cumplimiento de la función administrativa. También se aplicarán a la Contraloría General de la República, a las Fuerzas Armadas y a las Fuerzas de Orden y Seguridad Pública, a los gobiernos regionales y a las municipalidades. Las referencias que esta ley haga a la Administración o a la Administración del Estado, se entenderán efectuadas a los órganos y organismos señalados en el inciso precedente | I15: =IF(H15=H14,I14+1,1) -> 1
A16: FALSE | D16: Ley 19880 | E16: =VLOOKUP(D16,Normativa!$A$3:$C$100,3,0) -> Ley | H16: Artículo 3º. Concepto de Acto administrativo. Las decisiones escritas que adopte la Administración se expresarán por medio de actos administrativos. Para efectos de esta ley se entenderá por acto administrativo las decisiones formales que emitan los órganos de la Administración del Estado en las cuales se contienen declaraciones de voluntad, realizadas en el ejercicio de una potestad pública. Los actos administrativos tomarán la forma de decretos supremos y resoluciones. El decreto supremo es la orden escrita que dicta el Presidente de la República o un Ministro Por orden del Presidente de la República", sobre asuntos propios de su competencia. | I16: =IF(H16=H15,I15+1,1) -> 1
A17: FALSE | D17: Ley 19880 | E17: =VLOOKUP(D17,Normativa!$A$3:$C$100,3,0) -> Ley | H17: Las resoluciones son los actos de análoga naturaleza que dictan las autoridades administrativas dotadas de poder de decisión. | I17: =IF(H17=H16,I16+1,1) -> 1
A18: FALSE | D18: Ley 19880 | E18: =VLOOKUP(D18,Normativa!$A$3:$C$100,3,0) -> Ley | H18: Constituyen, también, actos administrativos los dictámenes o declaraciones de juicio, constancia o conocimiento que realicen los órganos de la Administración en el ejercicio de sus competencias. | I18: =IF(H18=H17,I17+1,1) -> 1
A19: FALSE | D19: Ley 19880 | E19: =VLOOKUP(D19,Normativa!$A$3:$C$100,3,0) -> Ley | H19: Las decisiones de los órganos administrativos pluripersonales se denominan acuerdos y se llevan a efecto por medio de resoluciones de la autoridad ejecutiva de la entidad correspondiente. | I19: =IF(H19=H18,I18+1,1) -> 1
A20: FALSE | D20: Ley 19880 | E20: =VLOOKUP(D20,Normativa!$A$3:$C$100,3,0) -> Ley | H20: Los actos administrativos gozan de una presunción de legalidad, de imperio y exigibilidad frente a sus destinatarios, desde su entrada en vigencia, autorizando su ejecución de oficio por la autoridad administrativa, salvo que mediare una orden de suspensión dispuesta por la autoridad administrativa dentro del procedimiento impugnatorio o por el juez, conociendo por la vía jurisdiccional. | I20: =IF(H20=H19,I19+1,1) -> 1
A21: FALSE | D21: Ley 19880 | E21: =VLOOKUP(D21,Normativa!$A$3:$C$100,3,0) -> Ley | I21: =IF(H21=H20,I20+1,1) -> 1
A22: FALSE | D22: Ley 19880 | E22: =VLOOKUP(D22,Normativa!$A$3:$C$100,3,0) -> Ley | H22: Artículo 4º. Principios del procedimiento. El procedimiento administrativo estará sometido a los principios de escrituración, gratuidad, celeridad, conclusivo, economía procedimental, contradictoriedad, imparcialidad, abstención, no formalización, inexcusabilidad, impugnabilidad, transparencia, publicidad y aquellos relativos a los medios electrónicos. | I22: =IF(H22=H21,I21+1,1) -> 1
A23: FALSE | D23: Ley 19880 | E23: =VLOOKUP(D23,Normativa!$A$3:$C$100,3,0) -> Ley | I23: =IF(H23=H22,I22+1,1) -> 1
A24: FALSE | D24: Ley 19880 | E24: =VLOOKUP(D24,Normativa!$A$3:$C$100,3,0) -> Ley | I24: =IF(H24=H23,I23+1,1) -> 2
A25: FALSE | D25: Ley 19880 | E25: =VLOOKUP(D25,Normativa!$A$3:$C$100,3,0) -> Ley | I25: =IF(H25=H24,I24+1,1) -> 3
A26: FALSE | D26: Ley 19880 | E26: =VLOOKUP(D26,Normativa!$A$3:$C$100,3,0) -> Ley | H26: Artículo 5º. Principio de escrituración. El procedimiento administrativo y los actos administrativos a los cuales da origen se expresarán por escrito a través de medios electrónicos, a menos que se configure alguna excepción establecida en la ley. | I26: =IF(H26=H25,I25+1,1) -> 1
A27: FALSE | D27: Ley 19880 | E27: =VLOOKUP(D27,Normativa!$A$3:$C$100,3,0) -> Ley | I27: =IF(H27=H26,I26+1,1) -> 1
A28: FALSE | D28: Ley 19880 | E28: =VLOOKUP(D28,Normativa!$A$3:$C$100,3,0) -> Ley | H28: Artículo 6º. Principio de gratuidad. En el procedimiento administrativo, las actuaciones que deban practicar los órganos de la Administración del Estado y la obtención de documentos e información necesaria para su conclusión serán gratuitas para los interesados, salvo disposición legal en contrario. No procederán cobros entre los órganos de la Administración del Estado que deban participar en su desarrollo e intercambio, salvo disposición legal en contrario. | I28: =IF(H28=H27,I27+1,1) -> 1
A29: FALSE | D29: Ley 19880 | E29: =VLOOKUP(D29,Normativa!$A$3:$C$100,3,0) -> Ley | I29: =IF(H29=H28,I28+1,1) -> 1
A30: FALSE | D30: Ley 19880 | E30: =VLOOKUP(D30,Normativa!$A$3:$C$100,3,0) -> Ley | H30: Artículo 7º. Principio de celeridad. El procedimiento, sometido al criterio de celeridad, se impulsará de oficio en todos sus trámites. | I30: =IF(H30=H29,I29+1,1) -> 1
A31: FALSE | D31: Ley 19880 | E31: =VLOOKUP(D31,Normativa!$A$3:$C$100,3,0) -> Ley | H31: Las autoridades y funcionarios de los órganos de la Administración del Estado deberán actuar por propia iniciativa en la iniciación del procedimiento de que se trate y en su prosecución, haciendo expeditos los trámites que debe cumplir el expediente y removiendo todo obstáculo que pudiere afectar a su pronta y debida decisión. | I31: =IF(H31=H30,I30+1,1) -> 1
A32: FALSE | D32: Ley 19880 | E32: =VLOOKUP(D32,Normativa!$A$3:$C$100,3,0) -> Ley | H32: En el despacho de los expedientes originados en una solicitud o en el ejercicio de un derecho se guardará el orden riguroso de ingreso en asuntos de similar naturaleza, salvo que por el titular de la unidad administrativa se dé orden motivada en contrario, de la que quede constancia. | I32: =IF(H32=H31,I31+1,1) -> 1
A33: FALSE | D33: Ley 19880 | E33: =VLOOKUP(D33,Normativa!$A$3:$C$100,3,0) -> Ley | H33: Artículo 8º. Principio conclusivo. Todo el procedimiento administrativo está destinado a que la Administración dicte un acto decisorio que se pronuncie sobre la cuestión de fondo y en el cual exprese su voluntad. | I33: =IF(H33=H32,I32+1,1) -> 1
A34: FALSE | D34: Ley 19880 | E34: =VLOOKUP(D34,Normativa!$A$3:$C$100,3,0) -> Ley | H34: Artículo 9º. Principio de economía procedimental. La Administración debe responder a la máxima economía de medios con eficacia, evitando trámites dilatorios. | I34: =IF(H34=H33,I33+1,1) -> 1
A35: FALSE | D35: Ley 19880 | E35: =VLOOKUP(D35,Normativa!$A$3:$C$100,3,0) -> Ley | H35: Se decidirán en un solo acto todos los trámites que, por su naturaleza, admitan un impulso simultáneo, siempre que no sea obligatorio su cumplimiento sucesivo. | I35: =IF(H35=H34,I34+1,1) -> 1
A36: FALSE | B36: Siempre que ocurra una comunicación entre órganos de la Administración | C36: Toda comunicación entre órganos de la Administración que se practique en el marco del procedimiento se realizará por medios electrónicos, dejándose constancia del órgano requirente, el funcionario responsable que practica el requerimiento, destinatario, procedimiento a que corresponde, gestión que se encarga y el plazo establecido para su realización. | D36: Ley 19880 | E36: =VLOOKUP(D36,Normativa!$A$3:$C$100,3,0) -> Ley | F36: Obligación | G36: Órganos de la Administración del Estado | H36: Toda comunicación entre órganos de la Administración que se practique en el marco del procedimiento se realizará por medios electrónicos, dejándose constancia del órgano requirente, el funcionario responsable que practica el requerimiento, destinatario, procedimiento a que corresponde, gestión que se encarga y el plazo establecido para su realización. Asimismo, deberá remitirse una copia electrónica de tal comunicación a todos quienes figuren como interesados en el procedimiento administrativo de que se trate. | I36: =IF(H36=H35,I35+1,1) -> 1 | J36: Se cumple con la implementación de docDigital en todos los Órganos de la Administración del Estado
A37: FALSE | D37: Ley 19880 | E37: =VLOOKUP(D37,Normativa!$A$3:$C$100,3,0) -> Ley | H37: Las cuestiones incidentales que se susciten en el procedimiento, incluso las que se refieran a la nulidad de actuaciones, no suspenderán la tramitación del mismo, a menos que la Administración, por resolución fundada, determine lo contrario. | I37: =IF(H37=H36,I36+1,1) -> 1
A38: FALSE | D38: Ley 19880 | E38: =VLOOKUP(D38,Normativa!$A$3:$C$100,3,0) -> Ley | I38: =IF(H38=H37,I37+1,1) -> 1
A39: FALSE | D39: Ley 19880 | E39: =VLOOKUP(D39,Normativa!$A$3:$C$100,3,0) -> Ley | H39: Artículo 10. Principio de contradictoriedad. Los interesados podrán, en cualquier momento del procedimiento, aducir alegaciones y aportar documentos u otros elementos de juicio. | I39: =IF(H39=H38,I38+1,1) -> 1
A40: FALSE | D40: Ley 19880 | E40: =VLOOKUP(D40,Normativa!$A$3:$C$100,3,0) -> Ley | H40: Los interesados podrán, en todo momento, alegar defectos de tramitación, especialmente los que supongan paralización, infracción de los plazos señalados o la omisión de trámites que pueden ser subsanados antes de la resolución definitiva del asunto. Dichas alegaciones podrán dar lugar, si hubiere razones para ello, a la exigencia de la correspondiente responsabilidad disciplinaria. | I40: =IF(H40=H39,I39+1,1) -> 1
...

Sheet Relaciones
A3: Norma Técnica de Interoperabilidad 2023-12 | B3: Decreto MINSEGPRES 2021-4

Sheet Hoja 5
B1: Ideas
B2: Todas las entradas enviadas a esta fase
B3: Búsqueda
B4: Búsqueda
B5: 29 resultados de búsqueda cargados.
B7: Más reciente
B9: Temas
B11: Lista
B13: Mapa
B14: Comentarios Estrategia Gestión de Datos Mayo 2023
A16: 45068 | B16: Patricio Véjar•hace 5 días Se ve una estrategia bastante integral y acorde con los desafíos de implementación que contempla dar un salto cualitativo y cuantitativo necesario cumplir con el objetivo de lograr contar con un gobierno digital en el plazo estipulado.Solo algunos comentarios:2. Contexto.En este capítulo se hecha de menos un diagnóstico del nivel de conocimiento digital de la población – en última instancia propietarios de los datos que se busca gestionar -. La mayoría de la población carece de una adecuada educación digital que le permita reconocer la importancia de entregar información veraz y pertinente. Por esta razón pareciera razonable incorporar procesos educativos en la estrategia. Adicionalmente, la población ha mostrado tener un elevado nivel de desconfianza en las instituciones lo que conllevaría dificultades para contar con la participación colaborativa de los usuarios y las usuarias de los servicios estatales en los diversos nivelas, para asegurar la calidad de los datos a recolectar.3.4.3.1. Modelo federado de datosSeñala el primer párrafo que “cada organismo es dueño y responsable de sus datos”. Esto no sería correcto dado que la mayoría de los datos almacenados serían propiedad de los usuarios y las usuarias de los organismos lo que es reconocido en otros acápites del documento. Para ser coherentes cada organismo debería reconocerse como mero administrador de los datos en su poder.En el siguiente párrafo señala: “un organismo que actuará como &lt;&lt;Proveedor&gt;&gt; de datos, y otro como &lt;&lt;Consumidor&gt;&gt;. En estricto rigor con la interoperabilidad debería existir una relación bidireccional entre los distintos puntos de recolección y almacenamiento de datos más aún si se está trabajando con plataformas descentralizadas.En el párrafo posterior donde lista los distintos servicios que se dispondrán para interoperar se menciona el Directorio de Datos asignándole la exposición de la “oferta de datos” de la Administración del Estado. En mi opinión la forma más pertinente para mencionar la tarea del Directorio de Datos es “exposición de la disponibilidad de datos”.En relación al Catálogo de Servicios, no pareciera pertinente asignarle la tares de “descubrimiento de servicios” dado el carácter descentralizado del sistema en su conjunto y el carácter autónomo de los elementos integrantes de la Red de Interoperabilidad.Finalmente en el párrafo subsiguiente y en relación a “la actualización constante de los conjuntos de datos” se hecha de menos la presencia de estándares de calidad y pertinencia de los datos, y estos estándares deberían, a su vez, generar procedimientos de validación y procesos de optimización de la calidad de los datos. Actualizar conjuntos de datos de baja calidad incrementará las imprecisiones sistémicas existentes.
B17: Total votos a favor: 1, total votos en contra: 0
B18: 0
B19: 0 comentarios
B20: PROPUESTA
B21: Fortalecimiento de la coordinación
B23: Michel Figueroa Mardones•hace 5 días La estrategia de gestión de datos representa un esfuerzo global por darle articulación a los esfuerzo de producción, almacenamiento y difusión de los datos gubernamentales. Se valora positivamente la intensión de asumir una posición ante las problemáticas de la gestión de datos.Aunque es un primer esfuerzo por parte del ejecutivo, es necesario extender la aplicación de este tipo de estrategia a los otros poderes del Estado, buscando facilitar así la interacción y experiencia ciudadana con las diferentes manifestaciones estatales.Los mecanismos de gobernanza interactiva, propios de la estructuras múltinivel como la que se propone, requiere una capacidad de coordinación y liderazgo que no se ha visibilizado en el pasado en esta ni otras materias y que puede ser el principal obstáculo a la hora de implementar la estrategia en cuestión. Parece dable entonces, poner acento e las facultades de la autoridad de datos para poder llevar a cabo los esfuerzos de coordinación y de ser posible simplificar la estructura de gobernanza de datos.
B24: Total votos a favor: 1, total votos en contra: 0
B25: 0
B26: 0 comentarios
B27: PROPUESTA
B28: Comentarios y propuestas para la Estrategia de Gestión de Datos del Estado
B30: Emilio Muñoz•hace 6 días Sobre el alcance de la Estrategia de Gestión de DatosEn primer lugar, el texto menciona que "la protección de los derechos de las personas en el tratamiento de sus datos personales es materia de legislación y queda por definir la instancia a cargo de supervisar el cumplimiento de dicha normativa". Sin embargo, esta afirmación no es correcta porque la nueva Ley de Protección de Datos ya está próxima a ser promulgada y efectivamente contempla la creación de una agencia encargada de supervisar el cumplimiento de la normativa. Además, es conocido que la nueva ley será similar al Reglamento General de Protección de Datos de la Unión Europea. No dejemos pasar la oportunidad para promover la privacidad y la protección de datos de las personas en la Estrategia. Se puede hacer potenciando las línea de acción "Seguridad y protección de la privacidad" que ya existe en la hoja de ruta y que está sido poco desarrollada.Otro aspecto es que el documento resalta la importancia del Portal de Datos Abiertos. Sin embargo, es relevante tener en cuenta que este tipo de portales se basa en el paradigma de Gobierno Abierto o Estado Abierto, un concepto que no se menciona en la Estrategia y que podría considerarse como una línea de acción adicional. Este tipo de portales son el resultado de un proceso de apertura dentro de una organización, que requiere un esfuerzo previo para garantizar la pertinencia y calidad de los datos que se compartirán con el público. En este sentido, dicho esfuerzo previo se asemeja a las actividades propuestas en la estrategia de gestión de datos.En la misma línea, se menciona la generación de iniciativas de inteligencia artificial basadas en datos. Sin embargo, estas también podrían considerarse como productos, ya que requieren que las instituciones, sectores o temáticas tengan un cierto nivel de madurez en la gestión de datos. Las iniciativas de inteligencia artificial no se mencionan en el roadmap, solo se abordan como parte de las funciones del CDO.Otro aspecto relacionado con el alcance es la inclusión de otras organizaciones públicas, como municipios, empresas públicas, poderes del Estado, organizaciones autónomas, entre otras. Aunque la estrategia indica que se aplicará a todos los órganos de la Administración del Estado, sería importante aclarar si se considerarán las organizaciones mencionadas.Sobre el Ciclo de valor en la gestión de datosDado que los objetivos de la gestión de datos pasan por garantizar su calidad, en esta sección se sugiere incluir algunas cuestiones conceptuales, por ejemplo definir qué se entiende por "dato" según la presente Estrategia, así como enumerar los tipos o categorías de datos que el Estado pretende gobernar a través de la misma.Como sugerencia, en general se podría utilizar el término "tratamiento" para agrupar el conjunto de operaciones que se realizan sobre los datos, ya que es el término preferido en las normativas.Además, se recomienda revisar la referencia a las etapas respecto de la figura, por ejemplo nombra las etapas como N°3, N°4, pero la imagen no tiene las etapas numeradas. Se sugiere tambien aumentar el tamaño del texto.Sobre los Niveles de la EstrategiaNivel 1 - Nivel OrganizaciónEn mi opinión, los elementos proporcionados a este nivel serán fundamentales para una rápida adopción del marco de trabajo y el éxito de la estrategia de gestión de datos del Estado. En este sentido, la estrategia debería proponer mecanismos para institucionalizar la gobernanza de datos con la menor fricción posible. Dentro de las organizaciones, existen diversas unidades y partes interesadas que manejan datos desde diferentes perspectivas, como los departamentos de TIC, los departamentos de seguridad de la información, el área jurídica o de cumplimiento normativo, así como las propias unidades de negocio que utilizan y evalúan el valor de cada dato tratado. De hecho, actualmente son las unidades de negocio donde se están instalando las capacidades de análisis de datos o ciencia de datos.En razón de lo anterior, se sugiere proponer cómo la estrategia será adoptada por la organización y cómo se "conversará" con las unidades y partes interesadas mencionadas anteriormente.Esta interacción tomará mayor relevancia con la promulgación y puesta en marcha de las leyes de Ciberseguridad e Infraestructura Crítica, así como la actualización de la Ley de Protección de Datos, ya que es muy probable que involucren actividades similares a las que propone TOGAF y DAMA, como el levantamiento de procesos e identificación de activos de información al interior de la organización.En la misma línea, considero importante establecer el alcance y la jerarquía del rol del Encargado de Gestión de Datos. ¿Este rol estará por encima de las unidades y partes interesadas mencionadas anteriormente? Es necesario que este rol cuente con la autoridad necesaria para impulsar el avance de la estrategia; de lo contrario, el nivel estratégico (Gobierno Digital) podría ser requerido frecuentemente para intervenir con los jefes de servicio cuando surjan controversias con la implementación de la estrategia.Una idea para simplificar y evitar la creación de nuevos cargos o unidades es que la estrategia proporcione previamente las pautas que ayuden a identificar la unidad o la parte interesada más idónea para asumir el rol de Encargado de Gestión de Datos en la organización. Por supuesto, estas pautas deben considerar la complejidad y el propósito de la organización,Por último, aunque se menciona brevemente que la estrategia buscará en principio consolidar únicamente el dominio de Arquitectura de Datos, es importante tener en cuenta que abordar la implementación de dicho dominio requiere un gran esfuerzo previo por parte de la organización y del encargado para generar los insumos necesarios. Consultar el punto 9.2.3 del framework en https://pubs.opengroup.org/architecture/togaf9-doc/arch/Nivel 2 - Sectores o TemáticasSe sugiere que la estrategia establezca desde el principio los sectores y temáticas, las organizaciones participantes y una priorización basada en la complejidad y criticidad para los intereses del país. Algunos sectores son evidentes, como salud o seguridad pública. De esta manera, se facilitará la coordinación entre las organizaciones, definiendo los sectores y temáticas macro desde el principio, al tiempo que se conserva la libertad de las instituciones para agruparse por iniciativa propia. Además, se menciona que las instituciones que converjan en cada sector o temática conformarán hubs para definir sus estándares, semántica, codificaciones, clasificaciones y servicios compartidos. Sin embargo se recomienda que la División realice un levantamiento sobre cada una de estas materias y provea un set de definiciones iniciales, de modo que los hubs construyan a partir de una base previamente validada por la estrategia, ya que por lo demás las definiciones de los sectores y temáticas eventualmente también tendrán que “conversar” entre sí.En general, considero que el propósito articulador de este nivel debería comenzar por analizar lo que se está haciendo actualmente dentro de cada sector, tomando como insumo el levantamiento inicial entregado por Gobierno Digital, para luego identificar las brechas existentes y comenzar a trabajar desde ahí. En complemento, las mesas sectoriales y temáticas también deberían designar a un representante que interactúe con Gobierno Digital y con otras instancias como el Comité Estratégico cuando corresponda.En este nivel, la estrategia también debería incluir la participación o asesoría de otros actores transversales a nivel técnico, como la academia, la ciudadanía, el sector privado y entidades especializadas como el CLPT y las futuras agencias de ciberseguridad e infraestructura crítica y la agencia de protección de datos personales.Finalmente, se menciona la creación de un centro de datos, pero no queda claro si se refiere a infraestructura o a un concepto. Se sugiere que se defina claramente. En caso de que se refiera a infraestructura, se sugiere no incluirlo en la estrategia, ya que es un elemento más técnico y podría generar expectativas en el sector privado que la estrategia deberá abordar eventualmente. No obstante, la estrategia debería expresar la voluntad de buscar la colaboración público-privada y así generar sinergias que ayuden a alcanzar los objetivos y que beneficien a ambas partes.Nivel 3 - EstadoEn este nivel se le da amplia cobertura y relevancia a que la división proveerá los servicios compartidos de interoperabilidad (los Nodos o PISEE 2.0) y el Portal de Datos Abiertos. Sin embargo, a pesar de ser componentes importantes, el papel del Estado en este caso debería centrarse en actuar como un facilitador, entregando las pautas y definiciones iniciales y los instrumentos habilitantes que se utilizarán durante la ejecución de la estrategia.Las definiciones iniciales incluyen los elementos mencionados en los niveles anteriores, por ejemplo los lineamientos para identificar al encargado de gestión de datos en las organizaciones, los lineamientos tácticos para adoptar los Nodos y el levantamiento inicial de estándares, semánticas, codificaciones, clasificaciones, maestros de datos y servicios compartidos que se utilizarán en forma transversal y en los hubs sectoriales y temáticos definidos.En la misma línea, en la sección donde se describe el modelo federado, se mencionan una serie de herramientas que serían provistas por Gobierno Digital a las organizaciones (directorio de datos, catálogo de servicios, esquemas y gestor de acuerdos), sin embargo estas herramientas no están descritas en ninguna parte del documento ni tampoco se indica si ya existen o se desarrollarán. Sería ideal que Gobierno Digital las facilite desde el principio, al igual que las definiciones iniciales.Respecto a los instrumentos habilitantes, Gobierno Digital podría liderar el despliegue de actos administrativos que generen impulso en las instituciones, como resoluciones para mandatar el cumplimiento de la estrategia o incluso - por qué no - un instructivo presidencial con ese fin. Considero que se desarrolla poco una “ambición” normativa institucional y a nivel de políticas públicas, que es lo que debiese buscar la estrategia, que aspira a tener un Estado basado en datos (Data-driven) y materializar grandes cambios en la cultura y gestión de las organizaciones. Por ejemplo, para lograr estas grandes transformaciones parece muy atractivo promover el uso de la Arquitectura Empresarial, pero la sola implementación de la gobernanza de datos no es suficiente, ya que la Arquitectura Empresarial interviene prácticamente todo en la organización: procesos, estructuras, tecnologías, etc. por lo tanto podría durar muchos años. Aquí la Estrategia pódría decir expresamente que el Gobierno de Datos será el punto de partida y así se establece una expectativa sin dejar de lado la aspiración de llegar al objetivo mayor (Estado y políticas publicas basadas en datos).Otro instrumento facilitador que Gobierno Digital podría proporcionar es la gestión para asígnar recursos a organizaciones con menor madurez o capacidades instaladas, como municipios y servicios pequeños.Por último, otra recomendación es que la estrategia incluya indicadores de alto nivel y plazos más concretos, de modo que se pueda llevar a cabo una adecuada rendición de cuentas y medir el progreso, siendo coherente con el roadmap.Sobre el Modelo FederadoCreo que esta toda esta sección debería explicarse dentro de la estrategia a nivel de organizaciones, ya que el modelo federado mediantes los Nodos es lo que materializa el proceso de gestión de los datos en la organización.El Nodo es un habilitador muy potente que facilita el intercambio de datos desde organizaciones, sin embargo hay que considerar que dentro una institución pueden haber muchos sistemas, poca gobernanza sobre ellos, externalizaciones, tecnologías dispares, obsolescencia, etc. Por lo tanto la estrategia debería proporcionar, por ejemplo, los lineamientos tácticos y operativos de cómo implementar uno o varios Nodos dentro de una organización en funcion a las arquitecturas existentes.Adicionalmente, sugiero cambiar figura 6 por un esquema que refleje el funcionamiento del Nodo y el modelo federado como un flujo, para mayor claridad.Sobre el Director de Gobernanza de Datos del Estado (Chief Data Oficer)Se indica que su objetivo es impulsar las iniciativas de la hoja de ruta, pero al ser una función ejecutiva, su rol debería incluir también la responsabilidad de garantizar el cumplimiento de la hoja de ruta / roadmap.En general, las responsabilidades del cargo se asemejan más a las de un coordinador. Además, algunas actividades parecen estar relacionadas con las responsabilidades de Gobierno Digital como entidad, por ejemplo, "Proporcionar lineamientos técnicos". Sugiero incluir dentro de los objetivos del cargo la búsqueda de oportunidades para utilizar datos en la resolución de problemáticas públicas y en el diseño de políticas públicas basadas en evidencia.Sobre el Comité Estratégico de Datos del EstadoComo propuesta, sugiero incluir la participación de representantes de las mesas sectoriales o temáticas. De hecho, es posible que en la práctica, estos representantes sectoriales coincidan con las instituciones estratégicas que menciona el documento.Sobre Plataforma de seguimiento para la implementación de la EstrategiaSe sugiere agregar una descripción más detallada, ya que no queda claro si el portal estará orientado a la ciudadanía, a las instituciones o si será una herramienta de control de gestión para la división, o si cumplirá todas estas funciones.En esta sección es el único lugar donde se menciona que la estrategia tendrá grados de cumplimiento y plazos definidos. En línea con la recomendación en párrafos anteriores, sería ideal que la descripción de esta plataforma sea coherente con los indicadores de alto nivel y los tiempos del roadmap.Finalmente, en el esquema de la figura 8 aparece otra herramienta de gestión aparte de la plataforma de seguimiento, que es el Directorio de Datos, sin embargo, no está descrito en la estrategia y solo se nombra una vez. También es un concepto que sería interesante saber qué es, por eso se sugiere incluir una descripción.Sobre la hoja de rutaRecomendaría darle más relevancia a las Líneas de Acción, ya que son ejes temáticos basados en las brechas que se identificaron para el sector público chileno, según lo que consta en la introducción. Las líneas de acción se podrían dejar como el punto 3.4 antes la sección Niveles de la Estrategia.Sobre las iniciativas del roadmapSugiero generar una iniciativa orientada a instalar a los encargados de datos en las instituciones, ya que esta tarea requiere más tiempo y esfuerzo de coordinación que la conformación de comités y mesas sectoriales, por ejemplo.En la iniciativa sobre la creación de una Norma Técnica de Datos Abiertos, sugiero ampliar su alcance para los datos en general (Norma Técnica de Datos), ya que esto ayudaría a la estandarización y proporcionaría un mayor respaldo a las definiciones iniciales sobre semántica, codificación, clasificación y servicios compartidos de la estrategia. Posteriormente, dentro de la misma norma, se podrían incluir los lineamientos sobre el tratamiento de los datos que pueden ser abiertos. Otra idea sería asociar esta norma con la de Interoperabilidad de la Ley de Transformación Digital.En general, se sugiere dar mayor claridad a los plazos de las iniciativas del roadmap, evitando usar términos relativos como corto y largo plazo. Además, algunas iniciativas se entienden más como actividades que hitos y quizás se podrían agrupar o replantear con un nivel de abstracción similar. Finalmente sería conveniente visualizar el roadmap como una línea de tiempo para ayudar a su comprensión.######## FIN ########Muchas gracias por el espacio de participación.Como nota aparte: Puede que el sistema citizenlab.co sobre el cual está hecho participacion.digital.gob.cl tenga posibilidad de integrarse con ClaveÚnica, para autenticarse con este medio en lugar de usar conectores sociales. ClaveÚnica utiliza el estándar OpenID Connect en su implementación.
B31: Total votos a favor: 3, total votos en contra: 0
B32: 0
B33: 0 comentarios
B34: PROPUESTA
B35: Opinión del GobLab Universidad Adolfo Ibáñez
